#VRML_SIM R2023a utf8

EXTERNPROTO "https://raw.githubusercontent.com/cyberbotics/webots/R2023a/projects/objects/backgrounds/protos/TexturedBackground.proto"
EXTERNPROTO "https://raw.githubusercontent.com/cyberbotics/webots/R2023a/projects/objects/backgrounds/protos/TexturedBackgroundLight.proto"
EXTERNPROTO "https://raw.githubusercontent.com/cyberbotics/webots/R2023a/projects/objects/floors/protos/RectangleArena.proto"

WorldInfo {
}
Viewpoint {
  orientation -0.31027730843524853 0.09967139591621109 0.945406581691862 2.968002532396512
  position 1.761527351584 -0.32127962283331946 1.1364920833341938
}
TexturedBackground {
}
TexturedBackgroundLight {
}
RectangleArena {
  translation 0 0 -0.00975334
  floorSize 10 10
}
Robot {
  translation 0.07249474980638553 -0.17757835336510178 0.039822980574976144
  rotation 0.9482887971870464 0.31740881701528145 -3.241062207161625e-06 -3.141576782558152
  children [
    DEF body Shape {
      appearance PBRAppearance {
        baseColor 1 0.5 0
        metalness 0
      }
      geometry Box {
        size 0.3 0.1 0.05
      }
    }
    HingeJoint {
      jointParameters HingeJointParameters {
        position -5.413070376422461e-07
      }
      device [
        RotationalMotor {
        }
      ]
      endPoint Solid {
        translation -0.1 0.05999999999998504 4.2375528929614064e-08
        rotation 0.999999999999911 -2.950136304652627e-07 3.0191482786116656e-07 1.5700000003930357
        children [
          DEF wheel Shape {
            appearance PBRAppearance {
              metalness 0
            }
            geometry Cylinder {
              height 0.02
              radius 0.05
            }
          }
        ]
        boundingObject USE wheel
        physics DEF Pwheel Physics {
        }
        linearVelocity -3.2242374056643157e-06 4.2268310883617585e-06 -7.614629804636909e-08
        angularVelocity 1.0566038820472905e-05 -9.866676175626585e-07 4.1093865795498274e-07
      }
    }
    Hinge2Joint {
      jointParameters HingeJointParameters {
        position -2.9590972869698855e-07
      }
      jointParameters2 JointParameters {
        position 1.365945422816305e-07
      }
      device [
        RotationalMotor {
        }
      ]
      device2 [
        RotationalMotor {
        }
      ]
      endPoint Solid {
        translation 0.0999999918043265 0.060000013659451026 -1.7754587763784286e-08
        rotation 0.9999999999999953 6.829729136674506e-08 6.835167977034282e-08 1.5699997040902758
        children [
          USE wheel
        ]
        name "solid(4)"
        boundingObject USE wheel
        physics USE Pwheel
        linearVelocity -4.931461110576807e-06 4.359207725261772e-06 1.9209016686976335e-06
        angularVelocity 3.0742269612626895e-06 -6.547299801832787e-06 1.2248243996095738e-06
      }
    }
    Hinge2Joint {
      jointParameters HingeJointParameters {
        position 2.912851442746068e-07
      }
      jointParameters2 JointParameters {
        position -1.3968722365291876e-07
      }
      device [
        RotationalMotor {
        }
      ]
      device2 [
        RotationalMotor {
        }
      ]
      endPoint Solid {
        translation 0.09999999161876559 -0.06000001396871922 -1.74771127253573e-08
        rotation 0.9999999999999951 -6.984359146584832e-08 -6.989925230674463e-08 1.5700002912851492
        children [
          USE wheel
        ]
        name "solid(5)"
        boundingObject USE wheel
        physics USE Pwheel
        linearVelocity 3.1830233477312236e-06 -4.998203589845079e-06 1.7519963046067264e-06
        angularVelocity 2.8518607592743135e-06 -6.790161687075778e-06 6.122517210010381e-07
      }
    }
    HingeJoint {
      jointParameters HingeJointParameters {
        position -3.902205628886622e-07
      }
      device [
        RotationalMotor {
        }
      ]
      endPoint Solid {
        translation -0.10000000000000003 -0.05999999999997401 -5.585353795291864e-08
        rotation 0.9999999999993132 -8.548847169228669e-07 8.01692175405037e-07 1.57000033876719
        children [
          USE wheel
        ]
        name "solid(1)"
        boundingObject USE wheel
        physics USE Pwheel
        linearVelocity 3.92850043478976e-06 -4.573754512624903e-06 3.1966054720496754e-07
        angularVelocity 3.2236492567645657e-06 -6.55601272562598e-06 1.4456288542500181e-06
      }
    }
  ]
  name "woz"
  boundingObject USE body
  physics DEF Pbody Physics {
  }
}
